<?xml version="1.0" ?>
<!-- =================================================================================== -->
<!-- |    This document was autogenerated by xacro from mars_car_tiny_forward.urdf.xacro | -->
<!-- |    EDITING THIS FILE BY HAND IS NOT RECOMMENDED                                 | -->
<!-- =================================================================================== -->
<robot name="mars_car_tiny_forward">
  <link name="base_footprint"/>
  <joint name="footprint_joint" type="fixed">
    <origin rpy="0.00000 0.00000 0.000" xyz="0.00000 0.00000 0.00000"/>
    <parent link="base_footprint"/>
    <child link="base_link"/>
    <axis xyz="0.00000 0.00000 1.00000"/>
  </joint>
  <link name="base_link"/>
  <joint name="base_joint" type="fixed">
    <origin rpy="0.00000 0.00000 0.00000" xyz="0.00000 0.00000 0.00000"/>
    <parent link="base_link"/>
    <child link="Mars6Mars_Rover__Curiosity_1_0__-_whole_body_link"/>
    <axis xyz="0.00000 0.00000 1.00000"/>
  </joint>
  <joint name="arm1" type="revolute">
    <limit effort="10000.00000" lower="-1.57000" upper="1.57000" velocity="5.00000"/>
    <origin rpy="0.00000 0.00000 0.00000" xyz="0.16967 0.06330 -0.05090"/>
    <parent link="Mars6Mars_Rover__Curiosity_1_0__-_whole_body_link"/>
    <child link="Mars6Mars_Rover__Curiosity_1_0__-_15__Arm_Axle-2_link"/>
    <axis xyz="0.00000 0.00000 1.00000"/>
  </joint>
  <joint name="camera1" type="revolute">
    <limit effort="10000.00000" lower="-1.35000" upper="1.35000" velocity="5.00000"/>
    <origin rpy="0.00000 0.00000 0.00000" xyz="0.08930 -0.09970 0.13058"/>
    <parent link="Mars6Mars_Rover__Curiosity_1_0__-_whole_body_link"/>
    <child link="Mars6Mars_Rover__Curiosity_1_0__-_7__Matscam_Holder-1_link"/>
    <axis xyz="0.00000 0.00000 1.00000"/>
  </joint>
  <joint name="left_foot1" type="revolute">
    <limit effort="10000.00000" lower="-0.5000" upper="0.5000" velocity="5.00000"/>
    <origin rpy="0.00000 0.00000 0.00000" xyz="0.22877 0.03703 -0.11721"/>
    <parent link="Mars6Mars_Rover__Curiosity_1_0__-_28_Wheel_connector_1-2_link"/>
    <child link="Mars6Mars_Rover__Curiosity_1_0__-_33_Front_Wheel_Servo_mech_lin"/>
    <axis xyz="0.00000 0.00000 1.00000"/>
  </joint>
  <joint name="left_foot3" type="revolute">
    <limit effort="10000.00000" lower="-0.5000" upper="0.5000" velocity="5.00000"/>
    <origin rpy="0.00000 0.00000 0.00000" xyz="-0.14234 0.03054 -0.04748"/>
    <parent link="Mars6Mars_Rover__Curiosity_1_0__-_29_Wheel_Connector_2-2_link"/>
    <child link="Mars6Mars_Rover__Curiosity_1_0__-_33_Front_Wheel_Servo_mech.001"/>
    <axis xyz="0.00000 0.00000 1.00000"/>
  </joint>
  <joint name="left_hip" type="revolute">
    <limit effort="10000.00000" lower="-0.35000" upper="0.35000" velocity="5.00000"/>
    <origin rpy="0.00000 0.00000 0.00000" xyz="-0.00550 0.17316 -0.03460"/>
    <dynamics damping="5" friction="5"/>
    <parent link="Mars6Mars_Rover__Curiosity_1_0__-_whole_body_link"/>
    <child link="Mars6Mars_Rover__Curiosity_1_0__-_28_Wheel_connector_1-2_link"/>
    <axis xyz="0.00000 1.00000 0.00000"/>
  </joint>
  <joint name="left_knee" type="revolute">
    <limit effort="10000.00000" lower="-0.35000" upper="0.35000" velocity="5.00000"/>
    <origin rpy="0.00000 0.00000 0.00000" xyz="-0.13623 0.00791 -0.03870"/>
    <parent link="Mars6Mars_Rover__Curiosity_1_0__-_28_Wheel_connector_1-2_link"/>
    <child link="Mars6Mars_Rover__Curiosity_1_0__-_29_Wheel_Connector_2-2_link"/>
    <axis xyz="0.00000 1.00000 0.00000"/>
  </joint>
  <joint name="left_wheel1" type="continuous">
    <limit effort="10000.00000" lower="0" upper="0" velocity="5.00000"/>
    <origin rpy="0.00000 0.00000 0.00000" xyz="-0.00238 0.02702 -0.08314"/>
    <parent link="Mars6Mars_Rover__Curiosity_1_0__-_33_Front_Wheel_Servo_mech_lin"/>
    <child link="Mars6Mars_Rover__Curiosity_1_0__-_1__Rover_Wheel_left_1_link"/>
    <axis xyz="0.00000 1.00000 0.00000"/>
  </joint>
  <joint name="left_wheel2" type="continuous">
    <limit effort="10000.00000" lower="0" upper="0" velocity="5.00000"/>
    <origin rpy="0.00000 0.00000 0.00000" xyz="0.12267 0.08478 -0.15679"/>
    <parent link="Mars6Mars_Rover__Curiosity_1_0__-_29_Wheel_Connector_2-2_link"/>
    <child link="Mars6Mars_Rover__Curiosity_1_0__-_1__Rover_Wheel_left_2_link"/>
    <axis xyz="0.00000 1.00000 0.00000"/>
    <dynamics damping="1" friction="1"/>
  </joint>
  <joint name="left_wheel3" type="continuous">
    <limit effort="10000.00000" lower="0" upper="0" velocity="5.00000"/>
    <origin rpy="-0.00000 -0.00000 0.00000" xyz="-0.00965 0.02541 -0.08514"/>
    <parent link="Mars6Mars_Rover__Curiosity_1_0__-_33_Front_Wheel_Servo_mech.001"/>
    <child link="Mars6Mars_Rover__Curiosity_1_0__-_1__Rover_Wheel_left_3_link"/>
    <axis xyz="0.00000 1.00000 0.00000"/>
    <dynamics damping="1" friction="1"/>
  </joint>
  <joint name="right_foot1" type="revolute">
    <limit effort="10000.00000" lower="-0.5000" upper="0.5000" velocity="5.00000"/>
    <origin rpy="0.00000 0.00000 0.00000" xyz="0.22441 -0.04260 -0.11148"/>
    <parent link="Mars6Mars_Rover__Curiosity_1_0__-_28_Wheel_connector_1-2_001_li"/>
    <child link="Mars6Mars_Rover__Curiosity_1_0__-_33_Front_Wheel_Servo_mech.002"/>
    <axis xyz="0.00000 0.00000 1.00000"/>
  </joint>
  <joint name="right_foot3" type="revolute">
    <limit effort="10000.00000" lower="-0.5000" upper="0.5000" velocity="5.00000"/>
    <origin rpy="0.00000 0.00000 0.00000" xyz="-0.13920 -0.03213 -0.04813"/>
    <parent link="Mars6Mars_Rover__Curiosity_1_0__-_29_Wheel_Connector_2-2_001_li"/>
    <child link="Mars6Mars_Rover__Curiosity_1_0__-_33_Front_Wheel_Servo_mechanis"/>
    <axis xyz="0.00000 0.00000 1.00000"/>
  </joint>
  <joint name="right_hip" type="revolute">
    <limit effort="10000.00000" lower="-0.35000" upper="0.35000" velocity="5.00000"/>
    <origin rpy="0.00000 0.00000 0.00000" xyz="-0.00194 -0.18320 -0.03644"/>
    <dynamics damping="5" friction="5"/>
    <parent link="Mars6Mars_Rover__Curiosity_1_0__-_whole_body_link"/>
    <child link="Mars6Mars_Rover__Curiosity_1_0__-_28_Wheel_connector_1-2_001_li"/>
    <axis xyz="0.00000 1.00000 0.00000"/>
  </joint>
  <joint name="right_knee" type="revolute">
    <limit effort="10000.00000" lower="-0.35000" upper="0.35000" velocity="5.00000"/>
    <origin rpy="0.00000 0.00000 0.00000" xyz="-0.13786 -0.00966 -0.03981"/>
    <parent link="Mars6Mars_Rover__Curiosity_1_0__-_28_Wheel_connector_1-2_001_li"/>
    <child link="Mars6Mars_Rover__Curiosity_1_0__-_29_Wheel_Connector_2-2_001_li"/>
    <axis xyz="0.00000 1.00000 0.00000"/>
    <dynamics damping="1" friction="1"/>
  </joint>
  <joint name="right_wheel1" type="continuous">
    <limit effort="10000.00000" lower="0" upper="0" velocity="5.00000"/>
    <origin rpy="0.00000 0.00000 0.00000" xyz="0.00483 -0.02175 -0.08672"/>
    <parent link="Mars6Mars_Rover__Curiosity_1_0__-_33_Front_Wheel_Servo_mech.002"/>
    <child link="Mars6Mars_Rover__Curiosity_1_0__-_1__Rover_Wheel_right_1_link"/>
    <axis xyz="0.00000 1.00000 0.00000"/>
    <dynamics damping="1" friction="1"/>
  </joint>
  <joint name="right_wheel2" type="continuous">
    <limit effort="10000.00000" lower="0" upper="0" velocity="5.00000"/>
    <origin rpy="0.00000 0.00000 0.00000" xyz="0.12019 -0.08425 -0.15146"/>
    <parent link="Mars6Mars_Rover__Curiosity_1_0__-_29_Wheel_Connector_2-2_001_li"/>
    <child link="Mars6Mars_Rover__Curiosity_1_0__-_1__Rover_Wheel_right_2_link"/>
    <axis xyz="0.00000 1.00000 0.00000"/>
    <dynamics damping="1" friction="1"/>
  </joint>
  <joint name="right_wheel3" type="continuous">
    <limit effort="10000.00000" lower="0" upper="0" velocity="5.00000"/>
    <origin rpy="0.00000 0.00000 0.00000" xyz="-0.01339 -0.02340 -0.08101"/>
    <parent link="Mars6Mars_Rover__Curiosity_1_0__-_33_Front_Wheel_Servo_mechanis"/>
    <child link="Mars6Mars_Rover__Curiosity_1_0__-_1__Rover_Wheel_right_3_link"/>
    <axis xyz="0.00000 1.00000 0.00000"/>
    <dynamics damping="1" friction="1"/>
  </joint>
  <link name="Mars6Mars_Rover__Curiosity_1_0__-_15__Arm_Axle-2_link">
    <!-- <inertial>
      <inertia  ixx="0.5700150666605545" ixy="0" ixz="0" iyy="0.15454881685833902" iyz="0" izz="0.1553727490815158" />
      <origin rpy="0.00000 0.00000 0.00000" xyz="0.0 0.00 0.0"/>
      <mass value="5.00000"/>
    </inertial> -->
    <!-- <visual name="Mars6Mars_Rover__Curiosity_1_0__-_18_Drill_joint-1">
      <origin rpy="0.00000 0.00000 0.00000" xyz="0.33471 0.08633 0.18495"/>
      <material name="材质.003"/>
      <geometry>
        <mesh filename="file://$(find marscar_gazebo_ros2)/models/mars_car_tiny_forward/meshes/dae/Mars6Mars_Rover__Curiosity_1_0__-_18_Drill_joint-1.001.dae" scale="1.00000 1.00000 1.00000"/>
      </geometry>
    </visual> -->
  </link>
  <link name="Mars6Mars_Rover__Curiosity_1_0__-_1__Rover_Wheel_left_1_link">
    <collision name="Mars6Mars_Rover__Curiosity_1_0__-_1__Rover_Wheel_left_1_collisi">
      <origin rpy="1.78342 1.57080 0.17772" xyz="0.00027 -0.00215 0.00055"/>
      <geometry>
        <sphere radius="0.07790"/>
      </geometry>
    </collision>
    <inertial>
      <inertia ixx="0.015680337994991043" ixy="0" ixz="0" iyy="0.020197781386013337" iyz="0" izz="0.015688269997299446"/>
      <origin rpy="0.00000 0.00000 0.00000" xyz="0.00009 -0.00144 0.00018"/>
      <mass value="5.00000"/>
    </inertial>
    <visual name="Mars6Mars_Rover__Curiosity_1_0__-_1__Rover_Wheel_left_1">
      <origin rpy="0.00000 0.00000 0.00000" xyz="0.00000 0.00000 0.00000"/>
      <material name="材质.002"/>
      <geometry>
        <mesh filename="file:///home/hp/marscar_ws/install/marscar_gazebo_ros2/share/marscar_gazebo_ros2/models/mars_car_tiny_forward/meshes/dae/Mars6Mars_Rover__Curiosity_1_0__-_1__Rover_Wheel_left_1.001.dae" scale="1.00000 1.00000 1.00000"/>
      </geometry>
    </visual>
  </link>
  <link name="Mars6Mars_Rover__Curiosity_1_0__-_1__Rover_Wheel_left_2_link">
    <collision name="Mars6Mars_Rover__Curiosity_1_0__-_1__Rover_Wheel_left_2_collisi">
      <origin rpy="1.57080 0.00000 -3.14159" xyz="0.00055 -0.00203 0.00047"/>
      <geometry>
        <sphere radius="0.07790"/>
      </geometry>
    </collision>
    <inertial>
      <inertia ixx="0.015680337994991043" ixy="0" ixz="0" iyy="0.020197781386013337" iyz="0" izz="0.015688269997299446"/>
      <origin rpy="0.00000 0.00000 0.00000" xyz="0.00021 -0.00143 -0.00006"/>
      <mass value="5.00000"/>
    </inertial>
    <visual name="Mars6Mars_Rover__Curiosity_1_0__-_1__Rover_Wheel_left_2">
      <origin rpy="0.00000 0.00000 0.00000" xyz="0.00000 0.00000 0.00000"/>
      <material name="材质.002"/>
      <geometry>
        <mesh filename="file:///home/hp/marscar_ws/install/marscar_gazebo_ros2/share/marscar_gazebo_ros2/models/mars_car_tiny_forward/meshes/dae/Mars6Mars_Rover__Curiosity_1_0__-_1__Rover_Wheel_left_2.001.dae" scale="1.00000 1.00000 1.00000"/>
      </geometry>
    </visual>
  </link>
  <link name="Mars6Mars_Rover__Curiosity_1_0__-_1__Rover_Wheel_left_3_link">
    <collision name="Mars6Mars_Rover__Curiosity_1_0__-_1__Rover_Wheel_left_3_collisi">
      <origin rpy="1.57080 -0.00000 -3.14159" xyz="0.00059 -0.00203 0.00041"/>
      <geometry>
        <sphere radius="0.07790"/>
      </geometry>
    </collision>
    <inertial>
      <inertia ixx="0.015680337994991043" ixy="0" ixz="0" iyy="0.020197781386013337" iyz="0" izz="0.015688269997299446"/>
      <origin rpy="0.00000 0.00000 0.00000" xyz="0.00022 -0.00143 -0.00005"/>
      <mass value="5.00000"/>
    </inertial>
    <visual name="Mars6Mars_Rover__Curiosity_1_0__-_1__Rover_Wheel_left_3">
      <origin rpy="0.00000 0.00000 -0.00000" xyz="0.00000 -0.00000 0.00000"/>
      <material name="材质.002"/>
      <geometry>
        <mesh filename="file:///home/hp/marscar_ws/install/marscar_gazebo_ros2/share/marscar_gazebo_ros2/models/mars_car_tiny_forward/meshes/dae/Mars6Mars_Rover__Curiosity_1_0__-_1__Rover_Wheel_left_3.001.dae" scale="1.00000 1.00000 1.00000"/>
      </geometry>
    </visual>
  </link>
  <link name="Mars6Mars_Rover__Curiosity_1_0__-_1__Rover_Wheel_right_1_link">
    <collision name="Mars6Mars_Rover__Curiosity_1_0__-_1__Rover_Wheel_right_1_collis">
      <origin rpy="-1.57093 1.52197 0.00338" xyz="-0.00066 0.00193 0.00038"/>
      <geometry>
        <sphere radius="0.07790"/>
      </geometry>
    </collision>
    <inertial>
      <inertia ixx="0.015680337994991043" ixy="0" ixz="0" iyy="0.020197781386013337" iyz="0" izz="0.015688269997299446"/>
      <origin rpy="0.00000 0.00000 0.00000" xyz="-0.00023 0.00143 -0.00006"/>
      <mass value="5.00000"/>
    </inertial>
    <visual name="Mars6Mars_Rover__Curiosity_1_0__-_1__Rover_Wheel_right_1">
      <origin rpy="0.00000 0.00000 0.00000" xyz="-0.00023 0.00143 -0.00006"/>
      <material name="材质.002"/>
      <geometry>
        <mesh filename="file:///home/hp/marscar_ws/install/marscar_gazebo_ros2/share/marscar_gazebo_ros2/models/mars_car_tiny_forward/meshes/dae/Mars6Mars_Rover__Curiosity_1_0__-_1__Rover_Wheel_right_1.001.dae" scale="1.00000 1.00000 1.00000"/>
      </geometry>
    </visual>
  </link>
  <link name="Mars6Mars_Rover__Curiosity_1_0__-_1__Rover_Wheel_right_2_link">
    <collision name="Mars6Mars_Rover__Curiosity_1_0__-_1__Rover_Wheel_right_2_collis">
      <origin rpy="1.57080 0.00000 -3.14159" xyz="-0.00061 0.00203 0.00040"/>
      <geometry>
        <sphere radius="0.07790"/>
      </geometry>
    </collision>
    <inertial>
      <inertia ixx="0.015680337994991043" ixy="0" ixz="0" iyy="0.020197781386013337" iyz="0" izz="0.015688269997299446"/>
      <origin rpy="0.00000 0.00000 0.00000" xyz="-0.00021 0.00143 -0.00005"/>
      <mass value="5.00000"/>
    </inertial>
    <visual name="Mars6Mars_Rover__Curiosity_1_0__-_1__Rover_Wheel_right_2">
      <origin rpy="0.00000 0.00000 0.00000" xyz="0.00000 0.00000 0.00000"/>
      <material name="材质.002"/>
      <geometry>
        <mesh filename="file:///home/hp/marscar_ws/install/marscar_gazebo_ros2/share/marscar_gazebo_ros2/models/mars_car_tiny_forward/meshes/dae/Mars6Mars_Rover__Curiosity_1_0__-_1__Rover_Wheel_right_2.001.dae" scale="1.00000 1.00000 1.00000"/>
      </geometry>
    </visual>
  </link>
  <link name="Mars6Mars_Rover__Curiosity_1_0__-_1__Rover_Wheel_right_3_link">
    <collision name="Mars6Mars_Rover__Curiosity_1_0__-_1__Rover_Wheel_right_3_collis">
      <origin rpy="1.58277 0.03499 -3.13636" xyz="0.00056 0.00193 -0.00063"/>
      <geometry>
        <sphere radius="0.07790"/>
      </geometry>
    </collision>
    <inertial>
      <inertia ixx="0.015680337994991043" ixy="0" ixz="0" iyy="0.020197781386013337" iyz="0" izz="0.015688269997299446"/>
      <origin rpy="0.00000 0.00000 0.00000" xyz="-0.00026 0.00143 -0.00004"/>
      <mass value="5.00000"/>
    </inertial>
    <visual name="Mars6Mars_Rover__Curiosity_1_0__-_1__Rover_Wheel_right_3">
      <origin rpy="0.00000 0.00000 0.00000" xyz="0.00000 0.00000 0.00000"/>
      <material name="材质.002"/>
      <geometry>
        <mesh filename="file:///home/hp/marscar_ws/install/marscar_gazebo_ros2/share/marscar_gazebo_ros2/models/mars_car_tiny_forward/meshes/dae/Mars6Mars_Rover__Curiosity_1_0__-_1__Rover_Wheel_right_3.001.dae" scale="1.00000 1.00000 1.00000"/>
      </geometry>
    </visual>
  </link>
  <link name="Mars6Mars_Rover__Curiosity_1_0__-_28_Wheel_connector_1-2_001_li">
    <inertial>
      <inertia ixx="0.01586436102114739" ixy="0" ixz="0" iyy="0.1389335988966778" iyz="0" izz="0.13507964012734022"/>
      <origin rpy="0.00000 0.00000 0.00000" xyz="0.10977 -0.00456 -0.04567"/>
      <mass value="10.00000"/>
    </inertial>
    <visual name="Mars6Mars_Rover__Curiosity_1_0__-_28_Wheel_connector_1-2_001">
      <origin rpy="0.00000 0.00000 0.00000" xyz="0.08989 0.00000 -0.03121"/>
      <material name="材质.007"/>
      <geometry>
        <mesh filename="file:///home/hp/marscar_ws/install/marscar_gazebo_ros2/share/marscar_gazebo_ros2/models/mars_car_tiny_forward/meshes/dae/Mars6Mars_Rover__Curiosity_1_0__-_28_Wheel_connector_1-2_00.dae" scale="1.00000 1.00000 1.00000"/>
      </geometry>
    </visual>
  </link>
  <link name="Mars6Mars_Rover__Curiosity_1_0__-_28_Wheel_connector_1-2_link">
    <inertial>
      <inertia ixx="0.015864359967019633" ixy="0" ixz="0" iyy="0.1389335988966778" iyz="0" izz="0.13507963907321247"/>
      <origin rpy="0.00000 0.00000 0.00000" xyz="0.11332 0.00456 -0.04751"/>
      <mass value="10.00000"/>
    </inertial>
    <visual name="Mars6Mars_Rover__Curiosity_1_0__-_28_Wheel_connector_1-2">
      <origin rpy="0.00000 0.00000 0.00000" xyz="0.09345 0.00000 -0.03304"/>
      <material name="材质.007"/>
      <geometry>
        <mesh filename="file:///home/hp/marscar_ws/install/marscar_gazebo_ros2/share/marscar_gazebo_ros2/models/mars_car_tiny_forward/meshes/dae/Mars6Mars_Rover__Curiosity_1_0__-_28_Wheel_connector_1-2.001.dae" scale="1.00000 1.00000 1.00000"/>
      </geometry>
    </visual>
  </link>
  <link name="Mars6Mars_Rover__Curiosity_1_0__-_29_Wheel_Connector_2-2_001_li">
    <inertial>
      <inertia ixx="0.004092295328463539" ixy="0" ixz="0" iyy="0.011362644811934977" iyz="0" izz="0.008365089424103947"/>
      <origin rpy="0.00000 0.00000 0.00000" xyz="0.04148 -0.01770 -0.09031"/>
      <mass value="5.00000"/>
    </inertial>
    <visual name="Mars6Mars_Rover__Curiosity_1_0__-_29_Wheel_Connector_2-2_001">
      <origin rpy="0.00000 0.00000 0.00000" xyz="-0.02351 -0.01970 -0.04864"/>
      <material name="材质.007"/>
      <geometry>
        <mesh filename="file:///home/hp/marscar_ws/install/marscar_gazebo_ros2/share/marscar_gazebo_ros2/models/mars_car_tiny_forward/meshes/dae/Mars6Mars_Rover__Curiosity_1_0__-_29_Wheel_Connector_2-2_00.dae" scale="1.00000 1.00000 1.00000"/>
      </geometry>
    </visual>
  </link>
  <link name="Mars6Mars_Rover__Curiosity_1_0__-_29_Wheel_Connector_2-2_link">
    <inertial>
      <inertia ixx="0.004092295328463539" ixy="0" ixz="0" iyy="0.011362644811934977" iyz="0" izz="0.008365089424103947"/>
      <origin rpy="0.00000 0.00000 0.00000" xyz="0.04341 0.01950 -0.09326"/>
      <mass value="5.00000"/>
    </inertial>
    <visual name="Mars6Mars_Rover__Curiosity_1_0__-_29_Wheel_Connector_2-2">
      <origin rpy="0.00000 0.00000 0.00000" xyz="-0.02159 0.02151 -0.05158"/>
      <material name="材质.007"/>
      <geometry>
        <mesh filename="file:///home/hp/marscar_ws/install/marscar_gazebo_ros2/share/marscar_gazebo_ros2/models/mars_car_tiny_forward/meshes/dae/Mars6Mars_Rover__Curiosity_1_0__-_29_Wheel_Connector_2-2.001.dae" scale="1.00000 1.00000 1.00000"/>
      </geometry>
    </visual>
  </link>
  <link name="Mars6Mars_Rover__Curiosity_1_0__-_33_Front_Wheel_Servo_mech.001">
    <inertial>
      <inertia ixx="0.002352120044837628" ixy="0" ixz="0" iyy="0.0017273099964177177" iyz="0" izz="0.0011494207690713"/>
      <origin rpy="0.00000 0.00000 0.00000" xyz="-0.00607 -0.02996 -0.06059"/>
      <mass value="5.00000"/>
    </inertial>
    <visual name="Mars6Mars_Rover__Curiosity_1_0__-_33_Front_Wheel_Servo_mech.004">
      <origin rpy="0.00000 0.00000 0.00000" xyz="-0.00523 -0.02934 -0.05449"/>
      <material name="材质.007"/>
      <geometry>
        <mesh filename="file:///home/hp/marscar_ws/install/marscar_gazebo_ros2/share/marscar_gazebo_ros2/models/mars_car_tiny_forward/meshes/dae/Mars6Mars_Rover__Curiosity_1_0__-_33_Front_Wheel_Servo_mech.004.dae" scale="1.00000 1.00000 1.00000"/>
      </geometry>
    </visual>
  </link>
  <link name="Mars6Mars_Rover__Curiosity_1_0__-_33_Front_Wheel_Servo_mech.002">
    <inertial>
      <inertia ixx="0.0023420283542323846" ixy="0" ixz="0" iyy="0.0017433353748485582" iyz="0" izz="0.0011561288965861634"/>
      <origin rpy="0.00000 0.00000 0.00000" xyz="-0.00802 0.03211 -0.06195"/>
      <mass value="5.00000"/>
    </inertial>
    <visual name="Mars6Mars_Rover__Curiosity_1_0__-_33_Front_Wheel_Servo_mech.003">
      <origin rpy="0.00000 0.00000 0.00000" xyz="-0.00793 0.03150 -0.05579"/>
      <material name="材质.007"/>
      <geometry>
        <mesh filename="file:///home/hp/marscar_ws/install/marscar_gazebo_ros2/share/marscar_gazebo_ros2/models/mars_car_tiny_forward/meshes/dae/Mars6Mars_Rover__Curiosity_1_0__-_33_Front_Wheel_Servo_mech.003.dae" scale="1.00000 1.00000 1.00000"/>
      </geometry>
    </visual>
  </link>
  <link name="Mars6Mars_Rover__Curiosity_1_0__-_33_Front_Wheel_Servo_mech_lin">
    <inertial>
      <inertia ixx="0.0023568104222244273" ixy="0" ixz="0" iyy="0.0016739295079963347" iyz="0" izz="0.0011002880751135174"/>
      <origin rpy="0.00000 0.00000 0.00000" xyz="-0.00371 -0.02830 -0.05807"/>
      <mass value="5.00000"/>
    </inertial>
    <visual name="Mars6Mars_Rover__Curiosity_1_0__-_33_Front_Wheel_Servo_mech">
      <origin rpy="0.00000 0.00000 0.00000" xyz="-0.00362 -0.02768 -0.05191"/>
      <material name="材质.007"/>
      <geometry>
        <mesh filename="file:///home/hp/marscar_ws/install/marscar_gazebo_ros2/share/marscar_gazebo_ros2/models/mars_car_tiny_forward/meshes/dae/Mars6Mars_Rover__Curiosity_1_0__-_33_Front_Wheel_Servo_mech.005.dae" scale="1.00000 1.00000 1.00000"/>
      </geometry>
    </visual>
  </link>
  <link name="Mars6Mars_Rover__Curiosity_1_0__-_33_Front_Wheel_Servo_mechanis">
    <inertial>
      <inertia ixx="0.002346255170752066" ixy="0" ixz="0" iyy="0.0017549479286614136" iyz="0" izz="0.001168817186416394"/>
      <origin rpy="0.00000 0.00000 0.00000" xyz="-0.01215 0.03223 -0.05659"/>
      <mass value="5.00000"/>
    </inertial>
    <visual name="Mars6Mars_Rover__Curiosity_1_0__-_33_Front_Wheel_Servo_mech.005">
      <origin rpy="0.00000 0.00000 0.00000" xyz="-0.01140 0.03168 -0.05047"/>
      <material name="材质.007"/>
      <geometry>
        <mesh filename="file:///home/hp/marscar_ws/install/marscar_gazebo_ros2/share/marscar_gazebo_ros2/models/mars_car_tiny_forward/meshes/dae/Mars6Mars_Rover__Curiosity_1_0__-_33_Front_Wheel_Servo_mech.006.dae" scale="1.00000 1.00000 1.00000"/>
      </geometry>
    </visual>
  </link>
  <link name="Mars6Mars_Rover__Curiosity_1_0__-_7__Matscam_Holder-1_link">
    <inertial>
      <inertia ixx="0.033972907445050285" ixy="0" ixz="0" iyy="0.02910473861946099" iyz="0" izz="0.008096255098011493"/>
      <origin rpy="0.00000 0.00000 0.00000" xyz="0.00007 0.00182 0.00749"/>
      <mass value="10.00000"/>
    </inertial>
    <visual name="Mars6Mars_Rover__Curiosity_1_0__-_7__Matscam_Holder-1">
      <origin rpy="0.00000 0.00000 0.00000" xyz="0.00000 0.00000 0.00000"/>
      <material name="材质.003"/>
      <geometry>
        <mesh filename="file:///home/hp/marscar_ws/install/marscar_gazebo_ros2/share/marscar_gazebo_ros2/models/mars_car_tiny_forward/meshes/dae/Mars6Mars_Rover__Curiosity_1_0__-_7__Matscam_Holder-1.001.dae" scale="1.00000 1.00000 1.00000"/>
      </geometry>
    </visual>
  </link>
  <link name="Mars6Mars_Rover__Curiosity_1_0__-_whole_body_link">
    <collision name="Mars6Mars_Rover__Curiosity_1_0__-_whole_body_collision">
      <origin rpy="0.00000 0.00000 0.00000" xyz="0.05103 0.00563 0.01153"/>
      <geometry>
        <box size="0.29034 0.31436 0.20157"/>
      </geometry>
    </collision>
    <inertial>
      <inertia ixx="0.9296970128839942" ixy="0" ixz="0" iyy="1.8737618892545362" iyz="0" izz="2.2616942768650596"/>
      <origin rpy="0.00000 0.00000 0.00000" xyz="0.03982 -0.00313 -0.10695"/>
      <mass value="80.00000"/>
    </inertial>
    <visual name="Mars6Mars_Rover__Curiosity_1_0__-_whole_body">
      <origin rpy="0.00000 0.00000 0.00000" xyz="0.00000 0.00000 0.00000"/>
      <material name="Material.002"/>
      <geometry>
        <mesh filename="file:///home/hp/marscar_ws/install/marscar_gazebo_ros2/share/marscar_gazebo_ros2/models/mars_car_tiny_forward/meshes/dae/Mars6Mars_Rover__Curiosity_1_0__-_whole_body.001.dae" scale="1.00000 1.00000 1.00000"/>
      </geometry>
    </visual>
  </link>
  <!-- gazebo特定的扩展部分 -->
  <material name="Material.002">
    <color rgba="0.74902 0.46275 0.00392 1.00000"/>
  </material>
  <material name="材质.002">
    <color rgba="0.00000 0.00000 0.00784 1.00000"/>
  </material>
  <material name="材质.003">
    <color rgba="0.31765 0.80000 0.72941 1.00000"/>
  </material>
  <material name="材质.007">
    <color rgba="0.01961 0.00000 0.00000 1.00000"/>
  </material>
  <ros2_control name="GazeboSystem" type="system">
    <hardware>
      <plugin>gazebo_ros2_control/GazeboSystem</plugin>
    </hardware>
    <!-- <joint name="arm1">
      <command_interface name="effort">
        <param name="min">-1000</param>
        <param name="max">1000</param>
      </command_interface>
      <state_interface name="position">
        <param name="initial_value">1.0</param>
      </state_interface>
      <state_interface name="velocity"/>
      <state_interface name="effort"/>
    </joint> -->
    <joint name="camera1">
      <command_interface name="position">
        <param name="min">-10</param>
        <param name="max">10</param>
      </command_interface>
      <state_interface name="position"/>
      <state_interface name="velocity"/>
      <state_interface name="effort"/>
    </joint>
    <joint name="left_foot1">
      <command_interface name="position">
        <param name="min">-1</param>
        <param name="max">1</param>
      </command_interface>
      <state_interface name="position">

      </state_interface>
      <state_interface name="velocity"/>
      <state_interface name="effort"/>
    </joint>
    <joint name="left_foot3">
      <command_interface name="position">
        <param name="min">-1</param>
        <param name="max">1</param>
      </command_interface>
      <state_interface name="position"/>
      <state_interface name="velocity"/>
      <state_interface name="effort"/>
    </joint>
    <joint name="left_hip">
      <command_interface name="effort">
        <param name="min">-1000</param>
        <param name="max">1000</param>
      </command_interface>
      <state_interface name="position">
      </state_interface>
      <state_interface name="velocity"/>
      <state_interface name="effort"/>
    </joint>
    <joint name="right_foot1">
      <command_interface name="position">
        <param name="min">-1</param>
        <param name="max">1</param>
      </command_interface>
      <state_interface name="position">
      </state_interface>
      <state_interface name="velocity"/>
      <state_interface name="effort"/>
    </joint>
    <joint name="right_foot3">
      <command_interface name="position">
        <param name="min">-1</param>
        <param name="max">1</param>
      </command_interface>
      <state_interface name="position"/>
      <state_interface name="velocity"/>
      <state_interface name="effort"/>
    </joint>
    <joint name="right_hip">
      <command_interface name="effort">
        <param name="min">-1000</param>
        <param name="max">1000</param>
      </command_interface>
      <state_interface name="position"/>
      <state_interface name="velocity"/>
      <state_interface name="effort"/>
    </joint>
    <joint name="right_wheel1">
      <command_interface name="velocity">
        <param name="min">-1000</param>
        <param name="max">1000</param>
      </command_interface>
      <state_interface name="position"/>
      <state_interface name="velocity"/>
      <state_interface name="effort"/>
    </joint>
    <joint name="right_wheel2">
      <command_interface name="velocity">
        <param name="min">-1000</param>
        <param name="max">1000</param>
      </command_interface>
      <state_interface name="position"/>
      <state_interface name="velocity"/>
      <state_interface name="effort"/>
    </joint>
    <joint name="right_wheel3">
      <command_interface name="velocity">
        <param name="min">-1000</param>
        <param name="max">1000</param>
      </command_interface>
      <state_interface name="position"/>
      <state_interface name="velocity"/>
      <state_interface name="effort"/>
    </joint>
    <joint name="left_wheel1">
      <command_interface name="velocity">
        <param name="min">-1000</param>
        <param name="max">1000</param>
      </command_interface>
      <state_interface name="position"/>
      <state_interface name="velocity"/>
      <state_interface name="effort"/>
    </joint>
    <joint name="left_wheel2">
      <command_interface name="velocity">
        <param name="min">-1000</param>
        <param name="max">1000</param>
      </command_interface>
      <state_interface name="position"/>
      <state_interface name="velocity"/>
      <state_interface name="effort"/>
    </joint>
    <joint name="left_wheel3">
      <command_interface name="velocity">
        <param name="min">-1000</param>
        <param name="max">1000</param>
      </command_interface>
      <state_interface name="position"/>
      <state_interface name="velocity"/>
      <state_interface name="effort"/>
    </joint>
    <joint name="left_knee">
      <command_interface name="effort">
        <param name="min">-1000</param>
        <param name="max">1000</param>
      </command_interface>
      <state_interface name="position"/>
      <state_interface name="velocity"/>
      <state_interface name="effort"/>
    </joint>
    <joint name="right_knee">
      <command_interface name="effort">
        <param name="min">-1000</param>
        <param name="max">1000</param>
      </command_interface>
      <state_interface name="position"/>
      <state_interface name="velocity"/>
      <state_interface name="effort"/>
    </joint>
  </ros2_control>
  <gazebo>
    <plugin filename="libgazebo_ros2_control.so" name="marscar_gazebo_ros2_control">
      <parameters>/home/hp/marscar_ws/install/marscar_gazebo_ros2/share/marscar_gazebo_ros2/config/mars_car_controller.yaml</parameters>
    </plugin>
  </gazebo>
  <gazebo>
    <plugin filename="libgazebo_ros_odom.so" name="odom_pub_plugin">
      <update_rate>100</update_rate>
      <left_joint>left_wheel2</left_joint>
      <right_joint>right_wheel2</right_joint>
      <wheel_separation>0.287</wheel_separation>
      <wheel_diameter>0.066</wheel_diameter>
      <publish_odom>true</publish_odom>
      <publish_odom_tf>true</publish_odom_tf>
      <odometry_topic>odom</odometry_topic>
      <odometry_frame>odom</odometry_frame>
      <robot_base_frame>base_footprint</robot_base_frame>
    </plugin>
    <plugin filename="libball_shooter_plugin.so" name="ball_shooter_plugin">
      <projectile>
        <model_name>blue_projectile0</model_name>
        <link_name>link</link_name>
        <frame>Mars6Mars_Rover__Curiosity_1_0__-_7__Matscam_Holder-1_link</frame>
        <pose>0.2 0 0 0 0 0</pose>
      </projectile>
      <shot_force>2000</shot_force>
      <topic>my_robot/ball_shooter/fire</topic>
    </plugin>
  </gazebo>
  <!-- Specify some standard inertial calculations https://en.wikipedia.org/wiki/List_of_moments_of_inertia -->
  <!-- These make use of xacro's mathematical functionality -->
  <joint name="camera_joint" type="fixed">
    <parent link="Mars6Mars_Rover__Curiosity_1_0__-_whole_body_link"/>
    <child link="camera_link"/>
    <origin rpy="0 0.0 0" xyz="0.0 0 0.3"/>
  </joint>
  <link name="camera_link">
    <visual>
      <geometry>
        <box size="0.010 0.03 0.03"/>
      </geometry>
    </visual>
    <visual>
      <origin xyz="0 0 -0.05"/>
      <geometry>
        <cylinder length="0.1" radius="0.002"/>
      </geometry>
    </visual>
  </link>
  <joint name="camera_optical_joint" type="fixed">
    <parent link="camera_link"/>
    <child link="camera_link_optical"/>
    <origin rpy="-1.5707963267948966 0 -1.5707963267948966" xyz="0 0 0"/>
  </joint>
  <link name="camera_link_optical"/>
  <gazebo reference="camera_link">
    <material>Gazebo/Black</material>
    <sensor name="camera1" type="camera">
      <update_rate>30</update_rate>
      <visualize>0</visualize>
      <camera name="head">
        <!-- <horizontal_fov>1.3962634</horizontal_fov> -->
        <image>
          <width>640</width>
          <height>480</height>
          <format>R8G8B8</format>
        </image>
        <!-- <clip>
              <near>0.02</near>
              <far>300</far>
            </clip> -->
        <!-- <noise>
              <type>gaussian</type>
              <mean>0.0</mean>
              <stddev>0.007</stddev>
            </noise> -->
      </camera>
      <plugin filename="libgazebo_ros_camera.so" name="camera_controller">
        <ros>
          <!-- TODO(louise) Remapping not working due to https://github.com/ros-perception/image_common/issues/93 -->
          <remapping>image_raw:=image_raw</remapping>
          <remapping>camera_info:=camera_info_demo</remapping>
        </ros>
        <!-- camera_name>omit so it defaults to sensor name</camera_name-->
        <!-- frame_name>omit so it defaults to link name</frame_name-->
      </plugin>
    </sensor>
  </gazebo>
  <gazebo reference="laser_frame">
    <material>Gazebo/Black</material>
    <sensor name="laser" type="ray">
      <pose> 0 0 0 0 0 0 </pose>
      <visualize>true</visualize>
      <update_rate>10</update_rate>
      <ray>
        <scan>
          <horizontal>
            <samples>360</samples>
            <min_angle>-3.14</min_angle>
            <max_angle>3.14</max_angle>
          </horizontal>
        </scan>
        <range>
          <min>0.3</min>
          <max>12</max>
        </range>
      </ray>
      <plugin filename="libgazebo_ros_ray_sensor.so" name="laser_controller">
        <ros>
          <argument>~/out:=scan</argument>
        </ros>
        <output_type>sensor_msgs/LaserScan</output_type>
        <frame_name>laser_frame</frame_name>
      </plugin>
    </sensor>
  </gazebo>
  <joint name="laser_joint" type="fixed">
    <parent link="Mars6Mars_Rover__Curiosity_1_0__-_whole_body_link"/>
    <child link="laser_frame"/>
    <origin rpy="0 0 0" xyz="0.0 0 0.1"/>
  </joint>
  <link name="laser_frame">
    <visual>
      <geometry>
        <cylinder length="0.04" radius="0.05"/>
      </geometry>
    </visual>
    <visual>
      <origin xyz="0 0 -0.05"/>
      <geometry>
        <cylinder length="0.1" radius="0.01"/>
      </geometry>
    </visual>
    <collision>
      <geometry>
        <cylinder length="0.04" radius="0.05"/>
      </geometry>
    </collision>
    <inertial>
      <origin rpy="0 0 0" xyz="0 0 0"/>
      <mass value="0.1"/>
      <inertia ixx="7.583333333333335e-05" ixy="0.0" ixz="0.0" iyy="7.583333333333335e-05" iyz="0.0" izz="0.00012500000000000003"/>
    </inertial>
  </link>
  <gazebo reference="imu_link">
    <sensor name="imu_sensor" type="imu">
      <plugin filename="libgazebo_ros_imu_sensor.so" name="imu_plugin">
        <ros>
          <namespace>/</namespace>
          <remapping>~/out:=imu</remapping>
        </ros>
        <initial_orientation_as_reference>true</initial_orientation_as_reference>
      </plugin>
      <always_on>true</always_on>
      <update_rate>100</update_rate>
    </sensor>
  </gazebo>
  <!-- imu质量 -->
  <!-- imu -->
  <joint name="imutobody" type="fixed">
    <origin rpy="0 0 0" xyz="0 0 0.02"/>
    <parent link="Mars6Mars_Rover__Curiosity_1_0__-_whole_body_link"/>
    <child link="imu_link"/>
  </joint>
  <link name="imu_link">
    <visual>
      <origin rpy="0 0 0" xyz="0 0 0"/>
      <geometry>
        <box size="0.01 0.01 0.01"/>
      </geometry>
      <material name="red">
        <color rgba="1.0 0.0 0.0 1.0"/>
      </material>
    </visual>
    <collision>
      <geometry>
        <box size="0.01 0.01 0.01"/>
      </geometry>
      <origin rpy="0.0 0.0 0.0" xyz="0.0 0.0 0"/>
    </collision>
    <inertial>
      <origin rpy="0 0 0" xyz="0 0 0"/>
      <mass value="0.1"/>
      <inertia ixx="7.583333333333335e-05" ixy="0.0" ixz="0.0" iyy="7.583333333333335e-05" iyz="0.0" izz="0.00012500000000000003"/>
    </inertial>
  </link>
  <gazebo reference="lidar_link">
    <material>Gazebo/Black</material>
    <sensor name="velodyne-HDL32E" type="gpu_ray">
      <pose>0 0 0 0 0 0</pose>
      <visualize>false</visualize>
      <update_rate>30</update_rate>
      <ray>
        <scan>
          <horizontal>
            <samples>2187</samples>
            <resolution>1</resolution>
            <min_angle>-3.141592653589793</min_angle>
            <max_angle>3.141592653589793</max_angle>
          </horizontal>
          <vertical>
            <samples>32</samples>
            <resolution>1</resolution>
            <min_angle>-0.5352924815866609</min_angle>
            <max_angle> 0.18622663118779495</max_angle>
          </vertical>
        </scan>
        <range>
          <min>0.3</min>
          <max>131</max>
          <resolution>0.001</resolution>
        </range>
        <noise>
          <type>gaussian</type>
          <mean>0.0</mean>
          <stddev>0.0</stddev>
        </noise>
      </ray>
      <plugin filename="libgazebo_ros_velodyne_laser.so" name="gazebo_ros_laser_controller">
        <ros>
          <namespace>/velodyne</namespace>
          <remapping>~/out:=/velodyne_points</remapping>
        </ros>
        <tf_prefix> </tf_prefix>
        <frame_name>lidar_link</frame_name>
        <organize_cloud>false</organize_cloud>
        <min_range>0.3</min_range>
        <max_range>130</max_range>
        <gaussian_noise>0.008</gaussian_noise>
      </plugin>
    </sensor>
  </gazebo>
  <joint name="lidar_joint" type="fixed">
    <parent link="Mars6Mars_Rover__Curiosity_1_0__-_whole_body_link"/>
    <child link="lidar_link"/>
    <origin rpy="0 0 0" xyz="0.0 0 0.2"/>
  </joint>
  <link name="lidar_link">
    <visual>
      <geometry>
        <cylinder length="0.04" radius="0.05"/>
      </geometry>
    </visual>
    <visual>
      <origin xyz="0 0 -0.05"/>
      <geometry>
        <cylinder length="0.1" radius="0.01"/>
      </geometry>
    </visual>
    <collision>
      <geometry>
        <cylinder length="0.04" radius="0.05"/>
      </geometry>
    </collision>
    <inertial>
      <origin rpy="0 0 0" xyz="0 0 0"/>
      <mass value="0.1"/>
      <inertia ixx="7.583333333333335e-05" ixy="0.0" ixz="0.0" iyy="7.583333333333335e-05" iyz="0.0" izz="0.00012500000000000003"/>
    </inertial>
  </link>
  <joint name="gps_joint" type="fixed">
    <parent link="Mars6Mars_Rover__Curiosity_1_0__-_whole_body_link"/>
    <child link="gps_link"/>
    <origin rpy="0 0.0 0" xyz="0.0 0 0.3"/>
  </joint>
  <link name="gps_link">
    <visual>
      <geometry>
        <box size="0.010 0.03 0.03"/>
      </geometry>
    </visual>
    <visual>
      <origin xyz="0 0 -0.05"/>
      <geometry>
        <cylinder length="0.1" radius="0.002"/>
      </geometry>
    </visual>
  </link>
  <gazebo reference="gps_link">
    <material>Gazebo/Black</material>
    <sensor name="my_gps" type="gps">
      <always_on>true</always_on>
      <update_rate>30</update_rate>
      <gps>
        <position_sensing>
          <horizontal>
            <noise type="gaussian">
              <mean>0.0</mean>
              <stddev>2e-4</stddev>
            </noise>
          </horizontal>
          <vertical>
            <noise type="gaussian">
              <mean>0.0</mean>
              <stddev>2e-4</stddev>
            </noise>
          </vertical>
        </position_sensing>
      </gps>
      <plugin filename="libgazebo_ros_gps_sensor.so" name="my_gps_plugin">
        <ros>
          <namespace>/gps</namespace>
          <remapping>~/out:=data</remapping>
        </ros>
      </plugin>
    </sensor>
  </gazebo>
  <joint name="multicamera_joint" type="fixed">
    <parent link="Mars6Mars_Rover__Curiosity_1_0__-_whole_body_link"/>
    <child link="multicamera_link"/>
    <origin rpy="0 0.0 0" xyz="0.0 0 0.3"/>
  </joint>
  <link name="multicamera_link">
    <visual>
      <geometry>
        <box size="0.010 0.03 0.03"/>
      </geometry>
    </visual>
    <visual>
      <origin xyz="0 0 -0.05"/>
      <geometry>
        <cylinder length="0.1" radius="0.002"/>
      </geometry>
    </visual>
  </link>
  <gazebo reference="multicamera_link">
    <material>Gazebo/Black</material>
    <sensor name="camera1" type="multicamera">
      <pose>0 -0.2 0 0 0 0</pose>
      <update_rate>60</update_rate>
      <visualize>true</visualize>
      <camera name="left">
        <horizontal_fov>0.7</horizontal_fov>
        <image>
          <width>640</width>
          <height>480</height>
          <format>R8G8B8</format>
        </image>
        <clip>
          <near>0.02</near>
          <far>300</far>
        </clip>
        <noise>
          <type>gaussian</type>
          <!-- Noise is sampled independently per pixel on each frame.
                   That pixel's noise value is added to each of its color
                   channels, which at that point lie in the range [0,1]. -->
          <mean>0.0</mean>
          <stddev>0.007</stddev>
        </noise>
      </camera>
      <camera name="right">
        <pose>0 0.2 0 0 0 0</pose>
        <horizontal_fov>0.7</horizontal_fov>
        <image>
          <width>640</width>
          <height>480</height>
          <format>R8G8B8</format>
        </image>
        <clip>
          <near>0.02</near>
          <far>300</far>
        </clip>
        <noise>
          <type>gaussian</type>
          <!-- Noise is sampled independently per pixel on each frame.
                   That pixel's noise value is added to each of its color
                   channels, which at that point lie in the range [0,1]. -->
          <mean>0.0</mean>
          <stddev>0.007</stddev>
        </noise>
      </camera>
      <plugin filename="libgazebo_ros_camera.so" name="camera_controller">
        <ros>
          <namespace>demo_cam</namespace>
          <!-- topics need to be prefixed with camera_name for remapping -->
          <remapping>mycamera/left/image_raw:=mycamera/left/image_demo</remapping>
          <remapping>mycamera/right/image_raw:=mycamera/right/image_demo</remapping>
          <remapping>mycamera/left/camera_info:=mycamera/left/camera_info_demo</remapping>
          <remapping>mycamera/right/camera_info:=mycamera/right/camera_info_demo</remapping>
        </ros>
        <camera_name>mycamera</camera_name>
        <!-- frame_name>omit so it defaults to link name</frame_name-->
        <!-- Specify if triggered camera -->
        <!-- <triggered>false</triggered> -->
      </plugin>
    </sensor>
  </gazebo>
  <gazebo reference="Mars6Mars_Rover__Curiosity_1_0__-_1__Rover_Wheel_left_3_link">
    <selfCollide>false</selfCollide>
    <kp>1000000.0</kp>
    <kd>1.0</kd>
    <mu1>10.0</mu1>
    <mu2>10.0</mu2>
    <minDepth>0.001</minDepth>
    <maxContacts>10</maxContacts>
    <implicitSpringDamper>1</implicitSpringDamper>
  </gazebo>
  <gazebo reference="Mars6Mars_Rover__Curiosity_1_0__-_1__Rover_Wheel_left_2_link">
    <selfCollide>false</selfCollide>
    <kp>1000000.0</kp>
    <kd>1.0</kd>
    <mu1>10.0</mu1>
    <mu2>10.0</mu2>
    <minDepth>0.001</minDepth>
    <maxContacts>10</maxContacts>
    <implicitSpringDamper>1</implicitSpringDamper>
  </gazebo>
  <gazebo reference="Mars6Mars_Rover__Curiosity_1_0__-_1__Rover_Wheel_left_1_link">
    <selfCollide>false</selfCollide>
    <kp>1000000.0</kp>
    <kd>1.0</kd>
    <mu1>10.0</mu1>
    <mu2>10.0</mu2>
    <minDepth>0.001</minDepth>
    <maxContacts>10</maxContacts>
    <implicitSpringDamper>1</implicitSpringDamper>
  </gazebo>
  <gazebo reference="Mars6Mars_Rover__Curiosity_1_0__-_1__Rover_Wheel_right_3_link">
    <selfCollide>false</selfCollide>
    <kp>1000000.0</kp>
    <kd>1.0</kd>
    <mu1>10.0</mu1>
    <mu2>10.0</mu2>
    <minDepth>0.001</minDepth>
    <maxContacts>10</maxContacts>
    <implicitSpringDamper>1</implicitSpringDamper>
  </gazebo>
  <gazebo reference="Mars6Mars_Rover__Curiosity_1_0__-_1__Rover_Wheel_right_2_link">
    <selfCollide>false</selfCollide>
    <kp>1000000.0</kp>
    <kd>1.0</kd>
    <mu1>10.0</mu1>
    <mu2>10.0</mu2>
    <minDepth>0.001</minDepth>
    <maxContacts>10</maxContacts>
    <implicitSpringDamper>1</implicitSpringDamper>
  </gazebo>
  <gazebo reference="Mars6Mars_Rover__Curiosity_1_0__-_1__Rover_Wheel_right_1_link">
    <selfCollide>false</selfCollide>
    <kp>1000000.0</kp>
    <kd>1.0</kd>
    <mu1>10.0</mu1>
    <mu2>10.0</mu2>
    <minDepth>0.001</minDepth>
    <maxContacts>10</maxContacts>
    <implicitSpringDamper>1</implicitSpringDamper>
  </gazebo>
  <!-- <xacro:include filename="$(find marscar_gazebo_ros2)/sensor_description/depth_camera.xacro"/> -->
</robot>
