<?xml version="1.0" ?>
<!-- =================================================================================== -->
<!-- |    This document was autogenerated by xacro from cartpole.xacro.urdf            | -->
<!-- |    EDITING THIS FILE BY HAND IS NOT RECOMMENDED                                 | -->
<!-- =================================================================================== -->
<robot name="cartopole" xmlns:xacro="http://www.ros.org/wiki/xacro">
  <xacro:macro name="cable" params="sphere_name joint_nameA joint_nameB link_name link_name_pre count" >
  
    <link name="${sphere_name}">
      <inertial>
        <origin rpy="0.000000 0.000000 0.000000" xyz="0.000000 0.000000 0.000000"/>
        <mass value="0.0100000"/>
        <inertia ixx="0.010000" ixy="0.000000" ixz="0.000000" iyy="0.010000" iyz="0.000000" izz="0.010000"/>
      </inertial>
      <visual>
        <origin rpy="0.000000 0.000000 0.000000" xyz="0.000000 0.000000 0.000000"/>
        <geometry>
          <sphere radius="0.0500"/>
        </geometry>
      </visual>
      <collision name="${sphere_name}">
        <geometry>
          <sphere radius="0.0500"/>
        </geometry>
      </collision>
    </link>
    
    <joint name="${joint_nameA}" type="revolute">

      <child link="${sphere_name}"/>
      <parent link="${link_name_pre}"/>
      <axis xyz="0.000000 1.570000 0.000000"/>
      <limit lower="-1.700000" upper="1.700000" effort="1000.0"  velocity="30" stiffness="70000"/>
      <dynamics damping="0.100000" friction="0.100000"/>
      <origin xyz="0.000000 0.000000 ${count}"/>
    </joint>

    <link name="${link_name}">
      <inertial>
        <origin rpy="0.000000 -0.000000 0.000000" xyz="0.000000 0.000000 0.000000"/>
        <mass value="0.0100000"/>
        <inertia ixx="0.010000" ixy="0.000000" ixz="0.000000" iyy="0.010000" iyz="0.000000" izz="0.010000"/>
      </inertial>
      <visual>
        <origin rpy="0.000000 0.00000 0.000000" xyz="0.000000 0.000000 ${count/2}"/>
        <geometry>
          <cylinder length="${-count}" radius="0.0500"/>
        </geometry>
      </visual>
      <collision name="${link_name}">
        <origin rpy="0.000000 0.00000 0.000000" xyz="0.000000 0.000000 ${count/2}"/>
        <geometry>
          <cylinder length="${-count}" radius="0.0500"/>
        </geometry>
      </collision>
    </link>
    <joint name="${joint_nameB}" type="revolute">

      <child link="${link_name}"/>
      <parent link="${sphere_name}"/>
      <axis xyz="1.570000 0.000000 0.000000"/>
      <limit lower="-1.700000" upper="1.700000" effort="1000.0"  velocity="30" stiffness="70000"/>
      <dynamics damping="0.100000" friction="0.100000"/>
      <origin xyz="0.000000 0.000000 0.00000"/>
    </joint>
    <gazebo reference="${link_name}">
      <material>Gazebo/Orange</material>
    </gazebo>
    <gazebo reference="${sphere_name}">
      <material>Gazebo/Orange</material>
    </gazebo>
  </xacro:macro>


  <link name="world"/>
  <link name="slideBar">
    <visual>
      <geometry>
        <box size="30 0.05 0.05"/>
      </geometry>
      <origin xyz="0 0 0"/>
      <material name="green">
        <color rgba="0 0.8 .8 1"/>
      </material>
    </visual>
    <inertial>
      <mass value="10"/>
      <inertia ixx="1.0" ixy="0.0" ixz="0.0" iyy="1.0" iyz="0.0" izz="1.0"/>
    </inertial>
  </link>
  <link name="yslideBar">

    <visual>
      <geometry>
        <box size="30 0.05 0.05"/>
      </geometry>
      <origin xyz="0 0 0"/>
      <material name="green">
        <color rgba="0 0.8 .8 1"/>
      </material>
    </visual>
    <inertial>
      <mass value="10"/>
      <inertia ixx="1.0" ixy="0.0" ixz="0.0" iyy="1.0" iyz="0.0" izz="1.0"/>
    </inertial>
  </link>

  <link name="cart">
    <visual>
      <geometry>
        <box size="0.5 0.5 0.2"/>
      </geometry>
      <origin xyz="0 0 0"/>
      <material name="blue">
        <color rgba="0 0 .8 1"/>
      </material>
    </visual>
    <inertial>
      <mass value="1"/>
      <inertia ixx="1.0" ixy="0.0" ixz="0.0" iyy="1.0" iyz="0.0" izz="1.0"/>
    </inertial>
  </link>
  <link name="tail">

    <visual>
      <geometry>
        <box size="0.5 0.5 0.2"/>
      </geometry>
      <origin xyz="0 0 0"/>
      <material name="blue">
        <color rgba="0 0 .8 1"/>
      </material>
    </visual>
    <inertial>
      <mass value="0.1"/>
      <inertia ixx="1.0" ixy="0.0" ixz="0.0" iyy="1.0" iyz="0.0" izz="1.0"/>
    </inertial>
  </link>
  <joint name="world_to_base" type="fixed">
    <origin rpy="0 0 0" xyz="33 17 2"/>
    <parent link="world"/>
    <child link="slideBar"/>
  </joint>
  <joint name="x_to_y" type="prismatic">
    <axis xyz="1 0 0"/>
    <origin xyz="0.0 0.0 0.0" rpy="0 0 0"/>
    <parent link="yslideBar"/>
    <child link="cart"/>
    <limit effort="1000.0" lower="-15" upper="15" velocity="30"/>
    <dynamics damping="100.0" friction="10.0"/>
  </joint>
  <joint name="slider_to_cart" type="prismatic">
    <axis xyz="0 1 0"/>
    <origin xyz="0.0 0.0 0.0" rpy="0 0 1.57"/>
    <parent link="slideBar"/>
    <child link="yslideBar"/>
    <limit effort="1000.0" lower="-15" upper="15" velocity="30"/>
    <dynamics damping="100.0" friction="10.0"/>
  </joint>

  <joint name="tail_joint" type="fixed">
    <origin rpy="0 0 0" xyz="0 0 0"/>
    <parent link="link100"/>
    <child link="tail"/>
  </joint>

  <!-- <joint name="tms" type="fixed">
    <origin rpy="0 0 0" xyz="0 0 0"/>
    <parent link="link100"/>
    <child link="rexrov/base_link"/>
  </joint> -->
<xacro:cable	sphere_name=	"sphere1"	joint_nameA=	"jointA1"	joint_nameB=	"jointB1"	link_name=	"link1"	link_name_pre=	"cart"	count="-0.3"/>
<xacro:cable	sphere_name=	"sphere2"	joint_nameA=	"jointA2"	joint_nameB=	"jointB2"	link_name=	"link2"	link_name_pre=	"link1"	count="-0.3"/>
<xacro:cable	sphere_name=	"sphere3"	joint_nameA=	"jointA3"	joint_nameB=	"jointB3"	link_name=	"link3"	link_name_pre=	"link2"	count="-0.3"/>
<xacro:cable	sphere_name=	"sphere4"	joint_nameA=	"jointA4"	joint_nameB=	"jointB4"	link_name=	"link4"	link_name_pre=	"link3"	count="-0.3"/>
<xacro:cable	sphere_name=	"sphere5"	joint_nameA=	"jointA5"	joint_nameB=	"jointB5"	link_name=	"link5"	link_name_pre=	"link4"	count="-0.3"/>
<xacro:cable	sphere_name=	"sphere6"	joint_nameA=	"jointA6"	joint_nameB=	"jointB6"	link_name=	"link6"	link_name_pre=	"link5"	count="-0.3"/>
<xacro:cable	sphere_name=	"sphere7"	joint_nameA=	"jointA7"	joint_nameB=	"jointB7"	link_name=	"link7"	link_name_pre=	"link6"	count="-0.3"/>
<xacro:cable	sphere_name=	"sphere8"	joint_nameA=	"jointA8"	joint_nameB=	"jointB8"	link_name=	"link8"	link_name_pre=	"link7"	count="-0.3"/>
<xacro:cable	sphere_name=	"sphere9"	joint_nameA=	"jointA9"	joint_nameB=	"jointB9"	link_name=	"link9"	link_name_pre=	"link8"	count="-0.3"/>
<xacro:cable	sphere_name=	"sphere10"	joint_nameA=	"jointA10"	joint_nameB=	"jointB10"	link_name=	"link10"	link_name_pre=	"link9"	count="-0.3"/>
<xacro:cable	sphere_name=	"sphere11"	joint_nameA=	"jointA11"	joint_nameB=	"jointB11"	link_name=	"link11"	link_name_pre=	"link10"	count="-0.3"/>
<xacro:cable	sphere_name=	"sphere12"	joint_nameA=	"jointA12"	joint_nameB=	"jointB12"	link_name=	"link12"	link_name_pre=	"link11"	count="-0.3"/>
<xacro:cable	sphere_name=	"sphere13"	joint_nameA=	"jointA13"	joint_nameB=	"jointB13"	link_name=	"link13"	link_name_pre=	"link12"	count="-0.3"/>
<xacro:cable	sphere_name=	"sphere14"	joint_nameA=	"jointA14"	joint_nameB=	"jointB14"	link_name=	"link14"	link_name_pre=	"link13"	count="-0.3"/>
<xacro:cable	sphere_name=	"sphere15"	joint_nameA=	"jointA15"	joint_nameB=	"jointB15"	link_name=	"link15"	link_name_pre=	"link14"	count="-0.3"/>
<xacro:cable	sphere_name=	"sphere16"	joint_nameA=	"jointA16"	joint_nameB=	"jointB16"	link_name=	"link16"	link_name_pre=	"link15"	count="-0.3"/>
<xacro:cable	sphere_name=	"sphere17"	joint_nameA=	"jointA17"	joint_nameB=	"jointB17"	link_name=	"link17"	link_name_pre=	"link16"	count="-0.3"/>
<xacro:cable	sphere_name=	"sphere18"	joint_nameA=	"jointA18"	joint_nameB=	"jointB18"	link_name=	"link18"	link_name_pre=	"link17"	count="-0.3"/>
<xacro:cable	sphere_name=	"sphere19"	joint_nameA=	"jointA19"	joint_nameB=	"jointB19"	link_name=	"link19"	link_name_pre=	"link18"	count="-0.3"/>
<xacro:cable	sphere_name=	"sphere20"	joint_nameA=	"jointA20"	joint_nameB=	"jointB20"	link_name=	"link20"	link_name_pre=	"link19"	count="-0.3"/>
<xacro:cable	sphere_name=	"sphere21"	joint_nameA=	"jointA21"	joint_nameB=	"jointB21"	link_name=	"link21"	link_name_pre=	"link20"	count="-0.3"/>
<xacro:cable	sphere_name=	"sphere22"	joint_nameA=	"jointA22"	joint_nameB=	"jointB22"	link_name=	"link22"	link_name_pre=	"link21"	count="-0.3"/>
<xacro:cable	sphere_name=	"sphere23"	joint_nameA=	"jointA23"	joint_nameB=	"jointB23"	link_name=	"link23"	link_name_pre=	"link22"	count="-0.3"/>
<xacro:cable	sphere_name=	"sphere24"	joint_nameA=	"jointA24"	joint_nameB=	"jointB24"	link_name=	"link24"	link_name_pre=	"link23"	count="-0.3"/>
<xacro:cable	sphere_name=	"sphere25"	joint_nameA=	"jointA25"	joint_nameB=	"jointB25"	link_name=	"link25"	link_name_pre=	"link24"	count="-0.3"/>
<xacro:cable	sphere_name=	"sphere26"	joint_nameA=	"jointA26"	joint_nameB=	"jointB26"	link_name=	"link26"	link_name_pre=	"link25"	count="-0.3"/>
<xacro:cable	sphere_name=	"sphere27"	joint_nameA=	"jointA27"	joint_nameB=	"jointB27"	link_name=	"link27"	link_name_pre=	"link26"	count="-0.3"/>
<xacro:cable	sphere_name=	"sphere28"	joint_nameA=	"jointA28"	joint_nameB=	"jointB28"	link_name=	"link28"	link_name_pre=	"link27"	count="-0.3"/>
<xacro:cable	sphere_name=	"sphere29"	joint_nameA=	"jointA29"	joint_nameB=	"jointB29"	link_name=	"link29"	link_name_pre=	"link28"	count="-0.3"/>
<xacro:cable	sphere_name=	"sphere30"	joint_nameA=	"jointA30"	joint_nameB=	"jointB30"	link_name=	"link30"	link_name_pre=	"link29"	count="-0.3"/>
<xacro:cable	sphere_name=	"sphere31"	joint_nameA=	"jointA31"	joint_nameB=	"jointB31"	link_name=	"link31"	link_name_pre=	"link30"	count="-0.3"/>
<xacro:cable	sphere_name=	"sphere32"	joint_nameA=	"jointA32"	joint_nameB=	"jointB32"	link_name=	"link32"	link_name_pre=	"link31"	count="-0.3"/>
<xacro:cable	sphere_name=	"sphere33"	joint_nameA=	"jointA33"	joint_nameB=	"jointB33"	link_name=	"link33"	link_name_pre=	"link32"	count="-0.3"/>
<xacro:cable	sphere_name=	"sphere34"	joint_nameA=	"jointA34"	joint_nameB=	"jointB34"	link_name=	"link34"	link_name_pre=	"link33"	count="-0.3"/>
<xacro:cable	sphere_name=	"sphere35"	joint_nameA=	"jointA35"	joint_nameB=	"jointB35"	link_name=	"link35"	link_name_pre=	"link34"	count="-0.3"/>
<xacro:cable	sphere_name=	"sphere36"	joint_nameA=	"jointA36"	joint_nameB=	"jointB36"	link_name=	"link36"	link_name_pre=	"link35"	count="-0.3"/>
<xacro:cable	sphere_name=	"sphere37"	joint_nameA=	"jointA37"	joint_nameB=	"jointB37"	link_name=	"link37"	link_name_pre=	"link36"	count="-0.3"/>
<xacro:cable	sphere_name=	"sphere38"	joint_nameA=	"jointA38"	joint_nameB=	"jointB38"	link_name=	"link38"	link_name_pre=	"link37"	count="-0.3"/>
<xacro:cable	sphere_name=	"sphere39"	joint_nameA=	"jointA39"	joint_nameB=	"jointB39"	link_name=	"link39"	link_name_pre=	"link38"	count="-0.3"/>
<xacro:cable	sphere_name=	"sphere40"	joint_nameA=	"jointA40"	joint_nameB=	"jointB40"	link_name=	"link40"	link_name_pre=	"link39"	count="-0.3"/>
<xacro:cable	sphere_name=	"sphere41"	joint_nameA=	"jointA41"	joint_nameB=	"jointB41"	link_name=	"link41"	link_name_pre=	"link40"	count="-0.3"/>
<xacro:cable	sphere_name=	"sphere42"	joint_nameA=	"jointA42"	joint_nameB=	"jointB42"	link_name=	"link42"	link_name_pre=	"link41"	count="-0.3"/>
<xacro:cable	sphere_name=	"sphere43"	joint_nameA=	"jointA43"	joint_nameB=	"jointB43"	link_name=	"link43"	link_name_pre=	"link42"	count="-0.3"/>
<xacro:cable	sphere_name=	"sphere44"	joint_nameA=	"jointA44"	joint_nameB=	"jointB44"	link_name=	"link44"	link_name_pre=	"link43"	count="-0.3"/>
<xacro:cable	sphere_name=	"sphere45"	joint_nameA=	"jointA45"	joint_nameB=	"jointB45"	link_name=	"link45"	link_name_pre=	"link44"	count="-0.3"/>
<xacro:cable	sphere_name=	"sphere46"	joint_nameA=	"jointA46"	joint_nameB=	"jointB46"	link_name=	"link46"	link_name_pre=	"link45"	count="-0.3"/>
<xacro:cable	sphere_name=	"sphere47"	joint_nameA=	"jointA47"	joint_nameB=	"jointB47"	link_name=	"link47"	link_name_pre=	"link46"	count="-0.3"/>
<xacro:cable	sphere_name=	"sphere48"	joint_nameA=	"jointA48"	joint_nameB=	"jointB48"	link_name=	"link48"	link_name_pre=	"link47"	count="-0.3"/>
<xacro:cable	sphere_name=	"sphere49"	joint_nameA=	"jointA49"	joint_nameB=	"jointB49"	link_name=	"link49"	link_name_pre=	"link48"	count="-0.3"/>
<xacro:cable	sphere_name=	"sphere50"	joint_nameA=	"jointA50"	joint_nameB=	"jointB50"	link_name=	"link50"	link_name_pre=	"link49"	count="-0.3"/>
<xacro:cable	sphere_name=	"sphere51"	joint_nameA=	"jointA51"	joint_nameB=	"jointB51"	link_name=	"link51"	link_name_pre=	"link50"	count="-0.3"/>
<xacro:cable	sphere_name=	"sphere52"	joint_nameA=	"jointA52"	joint_nameB=	"jointB52"	link_name=	"link52"	link_name_pre=	"link51"	count="-0.3"/>
<xacro:cable	sphere_name=	"sphere53"	joint_nameA=	"jointA53"	joint_nameB=	"jointB53"	link_name=	"link53"	link_name_pre=	"link52"	count="-0.3"/>
<xacro:cable	sphere_name=	"sphere54"	joint_nameA=	"jointA54"	joint_nameB=	"jointB54"	link_name=	"link54"	link_name_pre=	"link53"	count="-0.3"/>
<xacro:cable	sphere_name=	"sphere55"	joint_nameA=	"jointA55"	joint_nameB=	"jointB55"	link_name=	"link55"	link_name_pre=	"link54"	count="-0.3"/>
<xacro:cable	sphere_name=	"sphere56"	joint_nameA=	"jointA56"	joint_nameB=	"jointB56"	link_name=	"link56"	link_name_pre=	"link55"	count="-0.3"/>
<xacro:cable	sphere_name=	"sphere57"	joint_nameA=	"jointA57"	joint_nameB=	"jointB57"	link_name=	"link57"	link_name_pre=	"link56"	count="-0.3"/>
<xacro:cable	sphere_name=	"sphere58"	joint_nameA=	"jointA58"	joint_nameB=	"jointB58"	link_name=	"link58"	link_name_pre=	"link57"	count="-0.3"/>
<xacro:cable	sphere_name=	"sphere59"	joint_nameA=	"jointA59"	joint_nameB=	"jointB59"	link_name=	"link59"	link_name_pre=	"link58"	count="-0.3"/>
<xacro:cable	sphere_name=	"sphere60"	joint_nameA=	"jointA60"	joint_nameB=	"jointB60"	link_name=	"link60"	link_name_pre=	"link59"	count="-0.3"/>
<xacro:cable	sphere_name=	"sphere61"	joint_nameA=	"jointA61"	joint_nameB=	"jointB61"	link_name=	"link61"	link_name_pre=	"link60"	count="-0.3"/>
<xacro:cable	sphere_name=	"sphere62"	joint_nameA=	"jointA62"	joint_nameB=	"jointB62"	link_name=	"link62"	link_name_pre=	"link61"	count="-0.3"/>
<xacro:cable	sphere_name=	"sphere63"	joint_nameA=	"jointA63"	joint_nameB=	"jointB63"	link_name=	"link63"	link_name_pre=	"link62"	count="-0.3"/>
<xacro:cable	sphere_name=	"sphere64"	joint_nameA=	"jointA64"	joint_nameB=	"jointB64"	link_name=	"link64"	link_name_pre=	"link63"	count="-0.3"/>
<xacro:cable	sphere_name=	"sphere65"	joint_nameA=	"jointA65"	joint_nameB=	"jointB65"	link_name=	"link65"	link_name_pre=	"link64"	count="-0.3"/>
<xacro:cable	sphere_name=	"sphere66"	joint_nameA=	"jointA66"	joint_nameB=	"jointB66"	link_name=	"link66"	link_name_pre=	"link65"	count="-0.3"/>
<xacro:cable	sphere_name=	"sphere67"	joint_nameA=	"jointA67"	joint_nameB=	"jointB67"	link_name=	"link67"	link_name_pre=	"link66"	count="-0.3"/>
<xacro:cable	sphere_name=	"sphere68"	joint_nameA=	"jointA68"	joint_nameB=	"jointB68"	link_name=	"link68"	link_name_pre=	"link67"	count="-0.3"/>
<xacro:cable	sphere_name=	"sphere69"	joint_nameA=	"jointA69"	joint_nameB=	"jointB69"	link_name=	"link69"	link_name_pre=	"link68"	count="-0.3"/>
<xacro:cable	sphere_name=	"sphere70"	joint_nameA=	"jointA70"	joint_nameB=	"jointB70"	link_name=	"link70"	link_name_pre=	"link69"	count="-0.3"/>
<xacro:cable	sphere_name=	"sphere71"	joint_nameA=	"jointA71"	joint_nameB=	"jointB71"	link_name=	"link71"	link_name_pre=	"link70"	count="-0.3"/>
<xacro:cable	sphere_name=	"sphere72"	joint_nameA=	"jointA72"	joint_nameB=	"jointB72"	link_name=	"link72"	link_name_pre=	"link71"	count="-0.3"/>
<xacro:cable	sphere_name=	"sphere73"	joint_nameA=	"jointA73"	joint_nameB=	"jointB73"	link_name=	"link73"	link_name_pre=	"link72"	count="-0.3"/>
<xacro:cable	sphere_name=	"sphere74"	joint_nameA=	"jointA74"	joint_nameB=	"jointB74"	link_name=	"link74"	link_name_pre=	"link73"	count="-0.3"/>
<xacro:cable	sphere_name=	"sphere75"	joint_nameA=	"jointA75"	joint_nameB=	"jointB75"	link_name=	"link75"	link_name_pre=	"link74"	count="-0.3"/>
<xacro:cable	sphere_name=	"sphere76"	joint_nameA=	"jointA76"	joint_nameB=	"jointB76"	link_name=	"link76"	link_name_pre=	"link75"	count="-0.3"/>
<xacro:cable	sphere_name=	"sphere77"	joint_nameA=	"jointA77"	joint_nameB=	"jointB77"	link_name=	"link77"	link_name_pre=	"link76"	count="-0.3"/>
<xacro:cable	sphere_name=	"sphere78"	joint_nameA=	"jointA78"	joint_nameB=	"jointB78"	link_name=	"link78"	link_name_pre=	"link77"	count="-0.3"/>
<xacro:cable	sphere_name=	"sphere79"	joint_nameA=	"jointA79"	joint_nameB=	"jointB79"	link_name=	"link79"	link_name_pre=	"link78"	count="-0.3"/>
<xacro:cable	sphere_name=	"sphere80"	joint_nameA=	"jointA80"	joint_nameB=	"jointB80"	link_name=	"link80"	link_name_pre=	"link79"	count="-0.3"/>
<xacro:cable	sphere_name=	"sphere81"	joint_nameA=	"jointA81"	joint_nameB=	"jointB81"	link_name=	"link81"	link_name_pre=	"link80"	count="-0.3"/>
<xacro:cable	sphere_name=	"sphere82"	joint_nameA=	"jointA82"	joint_nameB=	"jointB82"	link_name=	"link82"	link_name_pre=	"link81"	count="-0.3"/>
<xacro:cable	sphere_name=	"sphere83"	joint_nameA=	"jointA83"	joint_nameB=	"jointB83"	link_name=	"link83"	link_name_pre=	"link82"	count="-0.3"/>
<xacro:cable	sphere_name=	"sphere84"	joint_nameA=	"jointA84"	joint_nameB=	"jointB84"	link_name=	"link84"	link_name_pre=	"link83"	count="-0.3"/>
<xacro:cable	sphere_name=	"sphere85"	joint_nameA=	"jointA85"	joint_nameB=	"jointB85"	link_name=	"link85"	link_name_pre=	"link84"	count="-0.3"/>
<xacro:cable	sphere_name=	"sphere86"	joint_nameA=	"jointA86"	joint_nameB=	"jointB86"	link_name=	"link86"	link_name_pre=	"link85"	count="-0.3"/>
<xacro:cable	sphere_name=	"sphere87"	joint_nameA=	"jointA87"	joint_nameB=	"jointB87"	link_name=	"link87"	link_name_pre=	"link86"	count="-0.3"/>
<xacro:cable	sphere_name=	"sphere88"	joint_nameA=	"jointA88"	joint_nameB=	"jointB88"	link_name=	"link88"	link_name_pre=	"link87"	count="-0.3"/>
<xacro:cable	sphere_name=	"sphere89"	joint_nameA=	"jointA89"	joint_nameB=	"jointB89"	link_name=	"link89"	link_name_pre=	"link88"	count="-0.3"/>
<xacro:cable	sphere_name=	"sphere90"	joint_nameA=	"jointA90"	joint_nameB=	"jointB90"	link_name=	"link90"	link_name_pre=	"link89"	count="-0.3"/>
<xacro:cable	sphere_name=	"sphere91"	joint_nameA=	"jointA91"	joint_nameB=	"jointB91"	link_name=	"link91"	link_name_pre=	"link90"	count="-0.3"/>
<xacro:cable	sphere_name=	"sphere92"	joint_nameA=	"jointA92"	joint_nameB=	"jointB92"	link_name=	"link92"	link_name_pre=	"link91"	count="-0.3"/>
<xacro:cable	sphere_name=	"sphere93"	joint_nameA=	"jointA93"	joint_nameB=	"jointB93"	link_name=	"link93"	link_name_pre=	"link92"	count="-0.3"/>
<xacro:cable	sphere_name=	"sphere94"	joint_nameA=	"jointA94"	joint_nameB=	"jointB94"	link_name=	"link94"	link_name_pre=	"link93"	count="-0.3"/>
<xacro:cable	sphere_name=	"sphere95"	joint_nameA=	"jointA95"	joint_nameB=	"jointB95"	link_name=	"link95"	link_name_pre=	"link94"	count="-0.3"/>
<xacro:cable	sphere_name=	"sphere96"	joint_nameA=	"jointA96"	joint_nameB=	"jointB96"	link_name=	"link96"	link_name_pre=	"link95"	count="-0.3"/>
<xacro:cable	sphere_name=	"sphere97"	joint_nameA=	"jointA97"	joint_nameB=	"jointB97"	link_name=	"link97"	link_name_pre=	"link96"	count="-0.3"/>
<xacro:cable	sphere_name=	"sphere98"	joint_nameA=	"jointA98"	joint_nameB=	"jointB98"	link_name=	"link98"	link_name_pre=	"link97"	count="-0.3"/>
<xacro:cable	sphere_name=	"sphere99"	joint_nameA=	"jointA99"	joint_nameB=	"jointB99"	link_name=	"link99"	link_name_pre=	"link98"	count="-0.3"/>
<xacro:cable	sphere_name=	"sphere100"	joint_nameA=	"jointA100"	joint_nameB=	"jointB100"	link_name=	"link100"	link_name_pre=	"link99"	count="-0.3"/>









  <ros2_control name="GazeboSystem" type="system">
    <hardware>
      <plugin>gazebo_ros2_control/GazeboSystem</plugin>
    </hardware>
    <joint name="slider_to_cart">
      <command_interface name="effort">
        <param name="min">-1000</param>
        <param name="max">1000</param>
      </command_interface>
      <state_interface name="position">
        <param name="initial_value">1.0</param>
      </state_interface>
      <state_interface name="velocity"/>
      <state_interface name="effort"/>
    </joint>

    <joint name="x_to_y">
      <command_interface name="effort">
        <param name="min">-1000</param>
        <param name="max">1000</param>
      </command_interface>
      <state_interface name="position"/>
      <state_interface name="velocity"/>
      <state_interface name="effort"/>
    </joint>
    
  </ros2_control>

  <gazebo>
    <plugin filename="libgazebo_ros2_control.so" name="gazebo_ros2_control">
      <parameters>$(find marscar_gazebo_ros2)/config/cartpole_controller_effort.yaml</parameters>
    </plugin>

  </gazebo>
  <gazebo reference="cart">
    <material>Gazebo/Orange</material>
  </gazebo>

  <gazebo reference="slideBar">
    <material>Gazebo/Red</material>
  </gazebo>

  <gazebo reference="yslideBar">
    <material>Gazebo/Blue</material>
  </gazebo>
</robot>
